<?xml version="1.0"?>
<!-- created with Phobos 1.0.1 "Capricious Choutengan" -->
  <robot name="6dof">

    <link name="link_1">
      <inertial>
        <origin xyz="0 0 0" rpy="0 0 0"/>
        <mass value="0.141"/>
        <inertia ixx="0.00012" ixy="0" ixz="0" iyy="2e-05" iyz="0" izz="2e-05"/>
      </inertial>
      <visual name="Main_Joint_1">
        <origin xyz="0 0 0" rpy="1.5708 0 0"/>
        <geometry>
          <mesh filename="package://test_pkg/meshes/dae/Main_Joint_1.dae" scale="1.0 1.0 1.0"/>
        </geometry>
        <material name="EVA01GreenLight"/>
      </visual>
      <collision name="Main_Joint_1">
        <origin xyz="0 0 0" rpy="1.5708 0 0"/>
        <geometry>
          <mesh filename="package://test_pkg/meshes/dae/Main_Joint_1.001.dae" scale="1.0 1.0 1.0"/>
        </geometry>
      </collision>
    </link>

    <link name="link_2_3">
      <inertial>
        <origin xyz="0 0 0" rpy="0 0 0"/>
        <mass value="0.327"/>
        <inertia ixx="0.001" ixy="0" ixz="0" iyy="0.001" iyz="0" izz="0.001"/>
      </inertial>
      <visual name="Main_CSF-8-30-1U_v2">
        <origin xyz="1e-05 0.146 0.02269" rpy="0 -1.5708 0"/>
        <geometry>
          <mesh filename="package://test_pkg/meshes/dae/Main_CSF-8-30-1U_v2.dae" scale="1.0 1.0 1.0"/>
        </geometry>
        <material name="EVA01GreenDark"/>
      </visual>
      <visual name="Main_CSF-8-30-1U_v2_1">
        <origin xyz="-1e-05 0 0.01996" rpy="0 -1.5708 0"/>
        <geometry>
          <mesh filename="package://test_pkg/meshes/dae/Main_CSF-8-30-1U_v2_1.dae" scale="1.0 1.0 1.0"/>
        </geometry>
        <material name="EVA01GreenDark"/>
      </visual>
      <visual name="Main_CaseJoint2_3">
        <origin xyz="0 0 0" rpy="0 -1.5708 0"/>
        <geometry>
          <mesh filename="package://test_pkg/meshes/dae/Main_CaseJoint2_3.dae" scale="1.0 1.0 1.0"/>
        </geometry>
        <material name="EVA01VioletLight"/>
      </visual>
      <visual name="Main_CaseOutside_1">
        <origin xyz="0.0018 0.12238 -0.00859" rpy="0 -1.5708 0"/>
        <geometry>
          <mesh filename="package://test_pkg/meshes/dae/Main_CaseOutside_1.dae" scale="1.0 1.0 1.0"/>
        </geometry>
        <material name="EVA01GreenLight"/>
      </visual>
      <visual name="Main_CaseOutside_2">
        <origin xyz="0.00263 0.0331 0.05514" rpy="0 -1.5708 0"/>
        <geometry>
          <mesh filename="package://test_pkg/meshes/dae/Main_CaseOutside_2.dae" scale="1.0 1.0 1.0"/>
        </geometry>
        <material name="EVA01GreenLight"/>
      </visual>
      <visual name="Main_Nema17_Slim">
        <origin xyz="0.00082 0.10757 0.01994" rpy="0 -1.5708 0"/>
        <geometry>
          <mesh filename="package://test_pkg/meshes/dae/Main_Nema17_Slim.dae" scale="1.0 1.0 1.0"/>
        </geometry>
        <material name="EVA01Purple"/>
      </visual>
      <visual name="Main_Nema17_StepperMotor">
        <origin xyz="0.00481 0.05535 0.01494" rpy="0 -1.5708 0"/>
        <geometry>
          <mesh filename="package://test_pkg/meshes/dae/Main_Nema17_StepperMotor.dae" scale="1.0 1.0 1.0"/>
        </geometry>
        <material name="EVA00Black"/>
      </visual>
      <collision name="Main_CaseJoint2_3">
        <origin xyz="0 0 0" rpy="0 -1.5708 0"/>
        <geometry>
          <mesh filename="package://test_pkg/meshes/dae/Main_CaseJoint2_3.001.dae" scale="1.0 1.0 1.0"/>
        </geometry>
      </collision>
    </link>

    <link name="link_4">
      <inertial>
        <origin xyz="0 0 0" rpy="0 0 0"/>
        <mass value="0.105"/>
        <inertia ixx="0.001" ixy="0" ixz="0" iyy="0.001" iyz="0" izz="0.001"/>
      </inertial>
      <visual name="Main_CSF-5-30-1U_v2">
        <!--origin xyz="-0.0223 0.05105 -0.03305" rpy="-1.55334 -1.55334 1.5708"/-->
        <origin xyz="-0.0223 0.05105 -0.03305" rpy="-2.3038 -1.55334 1.5708"/>
        <geometry>
          <mesh filename="package://test_pkg/meshes/dae/Main_CSF-5-30-1U_v2.dae" scale="1.0 1.0 1.0"/>
        </geometry>
        <material name="EVA00Black"/>
      </visual>
      <visual name="Main_CaseJoint4">
        <!--origin xyz="0 0 0" rpy="-1.55334 -1.55334 1.5708"/-->
        <origin xyz="0 0 0" rpy="-2.3038 -1.55334 1.5708"/>
        <geometry>
          <mesh filename="package://test_pkg/meshes/dae/Main_CaseJoint4.dae" scale="1.0 1.0 1.0"/>
        </geometry>
        <material name="EVA01VioletLight"/>
      </visual>
      <visual name="Main_CaseOutside_3">
        <!--origin xyz="-0.04394 0.05893 -0.03301" rpy="-1.55334 -1.55334 1.5708"/-->
        <origin xyz="-0.04394 0.05893 -0.03301" rpy="-2.3038 -1.55334 1.5708"/>
        <geometry>
          <mesh filename="package://test_pkg/meshes/dae/Main_CaseOutside_3.dae" scale="1.0 1.0 1.0"/>
        </geometry>
        <material name="EVA01GreenLight"/>
      </visual>
      <visual name="Main_PK513PA-H50S_v2">
        <!--origin xyz="-0.01762 0.07533 -0.03347" rpy="-1.55334 -1.55334 1.5708"/-->
        <origin xyz="-0.01762 0.07533 -0.03347" rpy="-2.3038 -1.55334 1.5708"/>
        <geometry>
          <mesh filename="package://test_pkg/meshes/dae/Main_PK513PA-H50S_v2.dae" scale="1.0 1.0 1.0"/>
        </geometry>
        <material name="EVA00Black"/>
      </visual>
      <collision name="Main_CaseJoint4">
        <!--origin xyz="0 0 0" rpy="-1.55334 -1.55334 1.5708"/-->
        <origin xyz="0 0 0" rpy="-2.3038 -1.55334 1.5708"/>
        <geometry>
          <mesh filename="package://test_pkg/meshes/dae/Main_CaseJoint4.001.dae" scale="1.0 1.0 1.0"/>
        </geometry>
      </collision>
    </link>

    <link name="link_5">
      <inertial>
        <origin xyz="0 0 0" rpy="0 0 0"/>
        <mass value="0.082"/>
        <inertia ixx="0.00101" ixy="0" ixz="0" iyy="0.00101" iyz="0" izz="0.00101"/>
      </inertial>
      <visual name="Main_CSF-5-30-1U_v2_1">
        <origin xyz="0.00259 0 0.127" rpy="0 3.14159 0"/>
        <geometry>
          <mesh filename="package://test_pkg/meshes/dae/Main_CSF-5-30-1U_v2_1.dae" scale="1.0 1.0 1.0"/>
        </geometry>
        <material name="EVA00Black"/>
      </visual>
      <visual name="Main_CaseJoint_5_1">
        <origin xyz="0 0 0" rpy="0 3.14159 0"/>
        <geometry>
          <mesh filename="package://test_pkg/meshes/dae/Main_CaseJoint_5_1.dae" scale="1.0 1.0 1.0"/>
        </geometry>
        <material name="EVA01VioletLight"/>
      </visual>
      <visual name="Main_CaseJoint_5_2">
        <origin xyz="0.0094 0.00049 0.09608" rpy="0 3.14159 0"/>
        <geometry>
          <mesh filename="package://test_pkg/meshes/dae/Main_CaseJoint_5_2.dae" scale="1.0 1.0 1.0"/>
        </geometry>
        <material name="EVA01VioletLight"/>
      </visual>
      <visual name="Main_CaseOutside_4">
        <origin xyz="0.02242 0.00045 0.07361" rpy="0 3.14159 0"/>
        <geometry>
          <mesh filename="package://test_pkg/meshes/dae/Main_CaseOutside_4.dae" scale="1.0 1.0 1.0"/>
        </geometry>
        <material name="EVA01GreenLight"/>
      </visual>
      <visual name="Main_ExtraPart2">
        <origin xyz="0.00534 -0.01233 0.03663" rpy="0 3.14159 0"/>
        <geometry>
          <mesh filename="package://test_pkg/meshes/dae/Main_ExtraPart2.dae" scale="1.0 1.0 1.0"/>
        </geometry>
        <material name="EVA01Purple"/>
      </visual>
      <visual name="Main_PK513PA-H50S_v2_1">
        <origin xyz="-0.00251 0 0.0549" rpy="0 3.14159 0"/>
        <geometry>
          <mesh filename="package://test_pkg/meshes/dae/Main_PK513PA-H50S_v2_1.dae" scale="1.0 1.0 1.0"/>
        </geometry>
        <material name="EVA00Black"/>
      </visual>
      <collision name="Main_CaseJoint_5_1">
        <origin xyz="0 0 0" rpy="0 3.14159 0"/>
        <geometry>
          <mesh filename="package://test_pkg/meshes/dae/Main_CaseJoint_5_1.001.dae" scale="1.0 1.0 1.0"/>
        </geometry>
      </collision>
      <collision name="Main_CaseJoint_5_2">
        <origin xyz="0.0094 0.00049 0.09608" rpy="0 3.14159 0"/>
        <geometry>
          <mesh filename="package://test_pkg/meshes/dae/Main_CaseJoint_5_2.001.dae" scale="1.0 1.0 1.0"/>
        </geometry>
      </collision>
    </link>

    <link name="link_6">
      <inertial>
        <origin xyz="0 0 0" rpy="0 0 0"/>
        <mass value="0.018"/>
        <inertia ixx="2e-05" ixy="0" ixz="0" iyy="2e-05" iyz="0" izz="2e-05"/>
      </inertial>
      <visual name="Main_CaseJoint_6">
        <origin xyz="0 0 0" rpy="0 -1.5708 0"/>
        <geometry>
          <mesh filename="package://test_pkg/meshes/dae/Main_CaseJoint_6.dae" scale="1.0 1.0 1.0"/>
        </geometry>
        <material name="EVA01VioletLight"/>
      </visual>
      <visual name="Main_CaseOutside_5">
        <origin xyz="0.01892 8e-05 0.01025" rpy="0 -1.5708 0"/>
        <geometry>
          <mesh filename="package://test_pkg/meshes/dae/Main_CaseOutside_5.dae" scale="1.0 1.0 1.0"/>
        </geometry>
        <material name="EVA01GreenLight"/>
      </visual>
      <visual name="Main_ExtraPart3">
        <origin xyz="0.04831 0.01225 -0.0068" rpy="0 -1.5708 0"/>
        <geometry>
          <mesh filename="package://test_pkg/meshes/dae/Main_ExtraPart3.dae" scale="1.0 1.0 1.0"/>
        </geometry>
        <material name="EVA01Purple"/>
      </visual>
      <visual name="Main_PK513PA-H50S_v1">
        <origin xyz="0.04794 0 -0.0068" rpy="0 -1.5708 0"/>
        <geometry>
          <mesh filename="package://test_pkg/meshes/dae/Main_PK513PA-H50S_v1.dae" scale="1.0 1.0 1.0"/>
        </geometry>
        <material name="EVA00Black"/>
      </visual>
      <visual name="Main_SH03W_KORP">
        <origin xyz="0.05151 0.01281 -0.00673" rpy="0 -1.5708 0"/>
        <geometry>
          <mesh filename="package://test_pkg/meshes/dae/Main_SH03W_KORP.dae" scale="1.0 1.0 1.0"/>
        </geometry>
        <material name="EVA01Purple"/>
      </visual>
      <visual name="Main_SHXX_PIN_5">
        <origin xyz="0.05065 0.01272 -0.00623" rpy="0 -1.5708 0"/>
        <geometry>
          <mesh filename="package://test_pkg/meshes/dae/Main_SHXX_PIN_5.dae" scale="1.0 1.0 1.0"/>
        </geometry>
        <material name="EVA02Orange"/>
      </visual>
      <visual name="Main_SHXX_PIN_6">
        <origin xyz="0.05065 0.01272 -0.00723" rpy="0 -1.5708 0"/>
        <geometry>
          <mesh filename="package://test_pkg/meshes/dae/Main_SHXX_PIN_6.dae" scale="1.0 1.0 1.0"/>
        </geometry>
        <material name="EVA02Orange"/>
      </visual>
      <collision name="Main_CaseJoint_6">
        <origin xyz="0 0 0" rpy="0 -1.5708 0"/>
        <geometry>
          <mesh filename="package://test_pkg/meshes/dae/Main_CaseJoint_6.001.dae" scale="1.0 1.0 1.0"/>
        </geometry>
      </collision>
    </link>

    <link name="link_gripper">
      <inertial>
        <origin xyz="0 0 0" rpy="0 0 0"/>
        <mass value="0.004"/>
        <inertia ixx="2e-05" ixy="0" ixz="0" iyy="2e-05" iyz="0" izz="2e-05"/>
      </inertial>
      <visual name="Gripper">
        <origin xyz="0 0 0" rpy="0 0 0"/>
        <geometry>
          <mesh filename="package://test_pkg/meshes/dae/Gripper.dae" scale="0.25 0.25 0.25"/>
        </geometry>
        <material name="EVA02Orange"/>
      </visual>
      <collision name="Gripper">
        <origin xyz="-0.00013 -0.00015 0.01246" rpy="0 0 0"/>
        <geometry>
          <box size="0.0125 0.01234 0.02512"/>
        </geometry>
      </collision>
    </link>

    <link name="root">
      <inertial>
        <origin xyz="0 0 0" rpy="0 0 0"/>
        <mass value="0.911"/>
        <inertia ixx="0.00268" ixy="0" ixz="0" iyy="2e-05" iyz="0" izz="2e-05"/>
      </inertial>
      <visual name="Main_Base">
        <origin xyz="0 0 0" rpy="1.5708 0 0"/>
        <geometry>
          <mesh filename="package://test_pkg/meshes/dae/Main_Base.dae" scale="1.0 1.0 1.0"/>
        </geometry>
        <material name="EVA01VioletLight"/>
      </visual>
      <visual name="Main_BotonLED">
        <origin xyz="-0.01182 -0.0515 -0.01961" rpy="1.5708 0 0"/>
        <geometry>
          <mesh filename="package://test_pkg/meshes/dae/Main_BotonLED.dae" scale="1.0 1.0 1.0"/>
        </geometry>
        <material name="Default"/>
      </visual>
      <visual name="Main_CRK543AP-H50">
        <origin xyz="0 -0.00319 -0.00114" rpy="1.5708 0 0"/>
        <geometry>
          <mesh filename="package://test_pkg/meshes/dae/Main_CRK543AP-H50.dae" scale="1.0 1.0 1.0"/>
        </geometry>
        <material name="Default"/>
      </visual>
      <visual name="Main_CaseButtons">
        <origin xyz="-0.00219 -0.05152 -0.0145" rpy="1.5708 0 0"/>
        <geometry>
          <mesh filename="package://test_pkg/meshes/dae/Main_CaseButtons.dae" scale="1.0 1.0 1.0"/>
        </geometry>
        <material name="EVA01GreenLight"/>
      </visual>
      <visual name="Main_ExtraPart1">
        <origin xyz="0 0.04315 -0.00422" rpy="1.5708 0 0"/>
        <geometry>
          <mesh filename="package://test_pkg/meshes/dae/Main_ExtraPart1.dae" scale="1.0 1.0 1.0"/>
        </geometry>
        <material name="EVA01GreenLight"/>
      </visual>
      <visual name="Main_SH05W_KORP">
        <origin xyz="0.02029 -0.05516 0.0145" rpy="1.5708 0 0"/>
        <geometry>
          <mesh filename="package://test_pkg/meshes/dae/Main_SH05W_KORP.dae" scale="1.0 1.0 1.0"/>
        </geometry>
        <material name="EVA01Purple"/>
      </visual>
      <visual name="Main_SHXX_PIN">
        <origin xyz="0.01952 -0.05506 0.0125" rpy="1.5708 0 0"/>
        <geometry>
          <mesh filename="package://test_pkg/meshes/dae/Main_SHXX_PIN.dae" scale="1.0 1.0 1.0"/>
        </geometry>
        <material name="EVA02Orange"/>
      </visual>
      <visual name="Main_SHXX_PIN_1">
        <origin xyz="0.01952 -0.05506 0.0135" rpy="1.5708 0 0"/>
        <geometry>
          <mesh filename="package://test_pkg/meshes/dae/Main_SHXX_PIN_1.dae" scale="1.0 1.0 1.0"/>
        </geometry>
        <material name="EVA02Orange"/>
      </visual>
      <visual name="Main_SHXX_PIN_2">
        <origin xyz="0.01952 -0.05506 0.0145" rpy="1.5708 0 0"/>
        <geometry>
          <mesh filename="package://test_pkg/meshes/dae/Main_SHXX_PIN_2.dae" scale="1.0 1.0 1.0"/>
        </geometry>
        <material name="EVA02Orange"/>
      </visual>
      <visual name="Main_SHXX_PIN_3">
        <origin xyz="0.01952 -0.05506 0.0155" rpy="1.5708 0 0"/>
        <geometry>
          <mesh filename="package://test_pkg/meshes/dae/Main_SHXX_PIN_3.dae" scale="1.0 1.0 1.0"/>
        </geometry>
        <material name="EVA02Orange"/>
      </visual>
      <visual name="Main_SHXX_PIN_4">
        <origin xyz="0.01952 -0.05506 0.0165" rpy="1.5708 0 0"/>
        <geometry>
          <mesh filename="package://test_pkg/meshes/dae/Main_SHXX_PIN_4.dae" scale="1.0 1.0 1.0"/>
        </geometry>
        <material name="EVA02Orange"/>
      </visual>
      <visual name="Main_Screen">
        <origin xyz="0.00144 -0.0611 0.01422" rpy="1.5708 0 0"/>
        <geometry>
          <mesh filename="package://test_pkg/meshes/dae/Main_Screen.dae" scale="1.0 1.0 1.0"/>
        </geometry>
        <material name="Default"/>
      </visual>
      <visual name="Main_Socket_2">
        <origin xyz="0.01804 -0.05643 -0.01953" rpy="1.5708 0 0"/>
        <geometry>
          <mesh filename="package://test_pkg/meshes/dae/Main_Socket_2.dae" scale="1.0 1.0 1.0"/>
        </geometry>
        <material name="EVA01Purple"/>
      </visual>
      <visual name="Main_Socket_5V">
        <origin xyz="0.00464 -0.06078 -0.0195" rpy="1.5708 0 0"/>
        <geometry>
          <mesh filename="package://test_pkg/meshes/dae/Main_Socket_5V.dae" scale="1.0 1.0 1.0"/>
        </geometry>
        <material name="EVA01Purple"/>
      </visual>
      <visual name="Main_Soporte">
        <origin xyz="0 -0.00016 -0.04472" rpy="1.5708 0 0"/>
        <geometry>
          <mesh filename="package://test_pkg/meshes/dae/Main_Soporte.dae" scale="1.0 1.0 1.0"/>
        </geometry>
        <material name="EVA01VioletDark"/>
      </visual>
      <collision name="Main_Base">
        <origin xyz="0 -0.00275 0.00128" rpy="1.5708 0 0"/>
        <geometry>
          <mesh filename="package://test_pkg/meshes/dae/Main_Base.001.dae" scale="1.0 1.0 1.0"/>
        </geometry>
      </collision>
    </link>

    <joint name="link_1" type="revolute">
      <origin xyz="0 -0.00275 0.0423" rpy="0 0 0"/>
      <parent link="root"/>
      <child link="link_1"/>
      <axis xyz="0 0 1.0"/>
      <limit lower="-3.14159" upper="3.14159" effort="3.5" velocity="52.35988"/>
    </joint>

    <joint name="link_2_3" type="revolute">
      <origin xyz="-0.0175 0.035 0.02548" rpy="1.5708 0 1.5708"/>
      <parent link="link_1"/>
      <child link="link_2_3"/>
      <axis xyz="0 0 1.0"/>
      <limit lower="-1.5708" upper="1.29154" effort="0.3" velocity="34.90659"/>
    </joint>

    <joint name="link_4" type="revolute">
      <origin xyz="0 0.146 0.04965" rpy="0.01745 0 1.5708"/>
      <parent link="link_2_3"/>
      <child link="link_4"/>
      <axis xyz="0 0 1.0"/>
      <limit lower="0.73304" upper="-1.5708" effort="0.17" velocity="26.17994"/>
    </joint>

    <joint name="link_5" type="revolute">
      <origin xyz="-0.01291 0.05121 -0.03305" rpy="1.55331 1.58825 1.57077"/>
      <parent link="link_4"/>
      <child link="link_5"/>
      <axis xyz="0 0 1.0"/>
      <limit lower="-3.14159" upper="3.14159" effort="0.4" velocity="2.61799"/>
    </joint>

    <joint name="link_6" type="revolute">
      <origin xyz="-0.0068 0 0.127" rpy="0 -1.5708 0"/>
      <parent link="link_5"/>
      <child link="link_6"/>
      <axis xyz="0 0 1.0"/>
      <limit lower="-2.35619" upper="2.35619" effort="0.4" velocity="2.61799"/>
    </joint>

    <joint name="link_gripper" type="revolute">
      <origin xyz="0.077 0 -0.0068" rpy="0 1.5708 0"/>
      <parent link="link_6"/>
      <child link="link_gripper"/>
      <axis xyz="0 0 1.0"/>
      <limit lower="-3.14159" upper="3.14159" effort="0.4" velocity="78.53982"/>
    </joint>

    <material name="Default">
      <color rgba="0.74902 0.74902 0.74902 1.0"/>
    </material>

    <material name="EVA00Black">
      <color rgba="0 0 0 1.0"/>
    </material>

    <material name="EVA01GreenDark">
      <color rgba="0.24706 0.42745 0.30588 1.0"/>
    </material>

    <material name="EVA01GreenLight">
      <color rgba="0.5451 0.83137 0.31372 1.0"/>
    </material>

    <material name="EVA01Purple">
      <color rgba="0.11372 0.10196 0.18431 1.0"/>
    </material>

    <material name="EVA01VioletDark">
      <color rgba="0.45098 0.3098 0.60392 1.0"/>
    </material>

    <material name="EVA01VioletLight">
      <color rgba="0.58824 0.37255 0.83137 1.0"/>
    </material>

    <material name="EVA02Orange">
      <color rgba="0.97647 0.61569 0.32157 1.0"/>
    </material>

  </robot>
